[2024-05-30T06:56:26.516+0000] {task_context_logger.py:104} ERROR - Executor reports task instance <TaskInstance: my_first_dag.print_hello scheduled__2024-05-29T00:00:00+00:00 [queued]> finished (failed) although the task says it's queued. (Info: None) Was the task killed externally?
