[2024-05-30T07:25:33.673+0000] {local_task_job_runner.py:120} INFO - ::group::Pre task execution logs
[2024-05-30T07:25:33.769+0000] {taskinstance.py:2076} INFO - Dependencies all met for dep_context=non-requeueable deps ti=<TaskInstance: testing_dag.choose_best_model scheduled__2024-05-29T00:00:00+00:00 [queued]>
[2024-05-30T07:25:33.814+0000] {taskinstance.py:2076} INFO - Dependencies all met for dep_context=requeueable deps ti=<TaskInstance: testing_dag.choose_best_model scheduled__2024-05-29T00:00:00+00:00 [queued]>
[2024-05-30T07:25:33.819+0000] {taskinstance.py:2306} INFO - Starting attempt 1 of 1
[2024-05-30T07:25:33.882+0000] {taskinstance.py:2330} INFO - Executing <Task(BranchPythonOperator): choose_best_model> on 2024-05-29 00:00:00+00:00
[2024-05-30T07:25:33.905+0000] {warnings.py:110} WARNING - /home/***/.local/lib/python3.12/site-packages/***/task/task_runner/standard_task_runner.py:61: DeprecationWarning: This process (pid=2923) is multi-threaded, use of fork() may lead to deadlocks in the child.
  pid = os.fork()

[2024-05-30T07:25:33.913+0000] {standard_task_runner.py:63} INFO - Started process 2925 to run task
[2024-05-30T07:25:33.914+0000] {standard_task_runner.py:90} INFO - Running: ['***', 'tasks', 'run', 'testing_dag', 'choose_best_model', 'scheduled__2024-05-29T00:00:00+00:00', '--job-id', '31', '--raw', '--subdir', 'DAGS_FOLDER/training_models.py', '--cfg-path', '/tmp/tmpqfkscm2g']
[2024-05-30T07:25:33.926+0000] {standard_task_runner.py:91} INFO - Job 31: Subtask choose_best_model
[2024-05-30T07:25:34.176+0000] {task_command.py:426} INFO - Running <TaskInstance: testing_dag.choose_best_model scheduled__2024-05-29T00:00:00+00:00 [running]> on host abdc8a9dc09e
[2024-05-30T07:25:34.536+0000] {taskinstance.py:2648} INFO - Exporting env vars: AIRFLOW_CTX_DAG_OWNER='***' AIRFLOW_CTX_DAG_ID='testing_dag' AIRFLOW_CTX_TASK_ID='choose_best_model' AIRFLOW_CTX_EXECUTION_DATE='2024-05-29T00:00:00+00:00' AIRFLOW_CTX_TRY_NUMBER='1' AIRFLOW_CTX_DAG_RUN_ID='scheduled__2024-05-29T00:00:00+00:00'
[2024-05-30T07:25:34.540+0000] {taskinstance.py:430} INFO - ::endgroup::
[2024-05-30T07:25:34.541+0000] {baseoperator.py:399} WARNING - BranchPythonOperator.execute cannot be called outside TaskInstance!
[2024-05-30T07:25:34.561+0000] {taskinstance.py:441} INFO - ::group::Post task execution logs
[2024-05-30T07:25:34.562+0000] {taskinstance.py:2905} ERROR - Task failed with exception
Traceback (most recent call last):
  File "/home/airflow/.local/lib/python3.12/site-packages/airflow/models/taskinstance.py", line 465, in _execute_task
    result = _execute_callable(context=context, **execute_callable_kwargs)
             ^^^^^^^^^^^^^^^^^^^^^^^^^^^^^^^^^^^^^^^^^^^^^^^^^^^^^^^^^^^^^
  File "/home/airflow/.local/lib/python3.12/site-packages/airflow/models/taskinstance.py", line 432, in _execute_callable
    return execute_callable(context=context, **execute_callable_kwargs)
           ^^^^^^^^^^^^^^^^^^^^^^^^^^^^^^^^^^^^^^^^^^^^^^^^^^^^^^^^^^^^
  File "/home/airflow/.local/lib/python3.12/site-packages/airflow/models/baseoperator.py", line 400, in wrapper
    return func(self, *args, **kwargs)
           ^^^^^^^^^^^^^^^^^^^^^^^^^^^
  File "/home/airflow/.local/lib/python3.12/site-packages/airflow/operators/python.py", line 269, in execute
    return self.do_branch(context, super().execute(context))
                                   ^^^^^^^^^^^^^^^^^^^^^^^^
  File "/home/airflow/.local/lib/python3.12/site-packages/airflow/models/baseoperator.py", line 400, in wrapper
    return func(self, *args, **kwargs)
           ^^^^^^^^^^^^^^^^^^^^^^^^^^^
  File "/home/airflow/.local/lib/python3.12/site-packages/airflow/operators/python.py", line 235, in execute
    return_value = self.execute_callable()
                   ^^^^^^^^^^^^^^^^^^^^^^^
  File "/home/airflow/.local/lib/python3.12/site-packages/airflow/operators/python.py", line 252, in execute_callable
    return self.python_callable(*self.op_args, **self.op_kwargs)
           ^^^^^^^^^^^^^^^^^^^^^^^^^^^^^^^^^^^^^^^^^^^^^^^^^^^^^
  File "/opt/airflow/dags/training_models.py", line 17, in _choose_best_model
    best_accuracy = max(accuracies)
                   ^^^^^^^^^^^^^^^
ValueError: max() iterable argument is empty
[2024-05-30T07:25:34.577+0000] {taskinstance.py:1206} INFO - Marking task as FAILED. dag_id=testing_dag, task_id=choose_best_model, run_id=scheduled__2024-05-29T00:00:00+00:00, execution_date=20240529T000000, start_date=20240530T072533, end_date=20240530T072534
[2024-05-30T07:25:34.605+0000] {standard_task_runner.py:110} ERROR - Failed to execute job 31 for task choose_best_model (max() iterable argument is empty; 2925)
[2024-05-30T07:25:34.658+0000] {local_task_job_runner.py:240} INFO - Task exited with return code 1
[2024-05-30T07:25:34.737+0000] {taskinstance.py:3498} INFO - 0 downstream tasks scheduled from follow-on schedule check
[2024-05-30T07:25:34.748+0000] {local_task_job_runner.py:222} INFO - ::endgroup::
